Workbook
Name ARPU: '07_ROI_Calculator'!$C$8
Name At_Risk_Count: '07_ROI_Calculator'!$C$7
Name CRM_Cost: '07_ROI_Calculator'!$C$10
Name Repeat_Spend: '07_ROI_Calculator'!$C$9

Sheet 01_Cover
B2: Olist Brazilian E-Commerce
B3: End-to-End Customer Analytics — SQL · RFM · Cohort · ROI
B5: Author | C5: Jen-Ho Cheng
B6: Role | C6: Data / Product Analyst — E-commerce
B7: Dataset | C7: Olist (Brazil) · 99,441 orders · 2016–2018
B9: THREE HEADLINE FINDINGS (formula-driven)
B11: ="R$ "&TEXT(_data_calc!$B$137/1000,"0")&"K" -> R$ 469K | C11: =TEXT(_data_calc!$B$139,"0.00%") -> 1.81% | D11: =TEXT(_data_calc!$B$138,"0.00")&"×" -> 3.48×
B12: Win-back revenue opportunity | C12: Cross-month repeat rate | D12: ARPU lift from 7-10 installments
B13: 21,975 at-risk customers · 9.4× ROI aggressive scenario | C13: Platform-level retention failure (vs. 5-15% mature benchmark) | D13: R$ 334 vs R$ 96 single payment — Brazil's hidden CRM
B14: → LIVE QUERY: Data → Queries & Connections → right-click 'qry_orders_live' → Load To... (M code fetches 99K orders fresh from GitHub raw)
B15: → INTERACTIVE PivotTable on sheet 10_Pivot_Analysis (drag fields to change view, right-click for Slicer, double-click to drill)
B17: SHEETS IN THIS WORKBOOK
B18: # | C18: Sheet | D18: What it shows
B19: 02 | C19: 02_Data_Dictionary | D19: 9-table schema + 3-row samples
B20: 03 | C20: 03_KPI_Dashboard | D20: Scale / Yearly KPIs / Status / Payment — XLOOKUP
B21: 04 | C21: 04_Revenue_Trend | D21: Monthly revenue + line chart
B22: 05 | C22: 05_RFM_Segments | D22: RFM segments (NTILE) + Pareto + icon set
B23: 06 | C23: 06_Cohort_Heatmap | D23: 13-month retention matrix (color scale)
B24: 07 | C24: 07_ROI_Calculator | D24: Live formulas + Named Ranges
B25: 08 | C25: 08_Installments | D25: AOV + repeat rate by installment bucket
B26: 09 | C26: 09_Logistics | D26: State ETA gap with 3-color scale
B27: 10 | C27: 10_Pivot_Analysis | D27: ★ Real PivotTable: state × payment_type
B30: LIVE LINKS
B31: Resource | C31: URL | D31: Description
B32: Streamlit App | C32: https://olist-jenho.streamlit.app/ | D32: Interactive 5-page dashboard
B33: HTML Dashboard | C33: https://kengkeng44.github.io/olist-project/ | D33: Static GitHub Pages
B34: Tableau Public | C34: https://public.tableau.com/app/profile/jenho.cheng/viz/2_17739060990590/1?publish=yes | D34: Tableau version
B35: GitHub Repo | C35: https://github.com/kengkeng44/olist-project | D35: Full source + SQL + notebook
B36: Pitch Deck | C36: https://github.com/kengkeng44/olist-project/blob/master/slides/portfolio.pdf | D36: 13-slide PM deck
B39: TECH STACK
B40: Python | C40: SQLite | D40: SQL (NTILE) | E40: pandas
B41: matplotlib | C41: Streamlit | D41: Tableau

Sheet 02_Data_Dictionary
B2: Data Dictionary
B3: 9 tables · 1.55M rows. 3-row samples below.
B5: 9 source tables
B6: Table | C6: Rows | D6: What's in it
B7: olist_orders_dataset | C7: 99441 | D7: Order header + 8 timestamps (purchase → delivery).
B8: olist_customers_dataset | C8: 99441 | D8: customer_id (per order) + customer_unique_id + ZIP.
B9: olist_order_items_dataset | C9: 112650 | D9: Line items: 1 row per (order, product, seller) with price + freight.
B10: olist_order_payments_dataset | C10: 103886 | D10: Payment type (boleto / credit_card / voucher / debit_card) + installments.
B11: olist_order_reviews_dataset | C11: 104719 | D11: 1-5 star reviews + comment text.
B12: olist_products_dataset | C12: 32951 | D12: Product attributes (category, weight, dimensions).
B13: olist_sellers_dataset | C13: 3095 | D13: Seller ZIP + state.
B14: olist_geolocation_dataset | C14: 1000163 | D14: ZIP-level lat/lng (state-level aggregations only).
B15: product_category_name_translation | C15: 71 | D15: PT->EN mapping for the 71 product categories.
B18: olist_orders_dataset.csv — first 3 rows
B19: order_id | C19: customer_id | D19: order_status | E19: order_purchase_timestamp | F19: order_approved_at | G19: order_delivered_carrier_date | H19: order_delivered_customer_date | I19: order_estimated_delivery_date
B20: e481f51cbdc54678b7cc49136f2d6af7 | C20: 9ef432eb6251297304e76186b10a928d | D20: delivered | E20: 2017-10-02 10:56:33 | F20: 2017-10-02 11:07:15 | G20: 2017-10-04 19:55:00 | H20: 2017-10-10 21:25:13 | I20: 2017-10-18 00:00:00
B21: 53cdb2fc8bc7dce0b6741e2150273451 | C21: b0830fb4747a6c6d20dea0b8c802d7ef | D21: delivered | E21: 2018-07-24 20:41:37 | F21: 2018-07-26 03:24:27 | G21: 2018-07-26 14:31:00 | H21: 2018-08-07 15:27:45 | I21: 2018-08-13 00:00:00
B22: 47770eb9100c2d0c44946d9cf07ec65d | C22: 41ce2a54c0b03bf3443c3d931a367089 | D22: delivered | E22: 2018-08-08 08:38:49 | F22: 2018-08-08 08:55:23 | G22: 2018-08-08 13:50:00 | H22: 2018-08-17 18:06:29 | I22: 2018-09-04 00:00:00
B24: olist_customers_dataset.csv — first 3 rows
B25: customer_id | C25: customer_unique_id | D25: customer_zip_code_prefix | E25: customer_city | F25: customer_state
B26: 06b8999e2fba1a1fbc88172c00ba8bc7 | C26: 861eff4711a542e4b93843c6dd7febb0 | D26: 14409 | E26: franca | F26: SP
B27: 879864dab9bc3047522c92c82e1212b8 | C27: 4c93744516667ad3b8f1fb645a3116a4 | D27: 89254 | E27: jaragua do sul | F27: SC
B28: 5e274e7a0c3809e14aba7ad5aae0d407 | C28: 57b2a98a409812fe9618067b6b8ebe4f | D28: 35182 | E28: timoteo | F28: MG
B30: olist_order_items_dataset.csv — first 3 rows
B31: order_id | C31: order_item_id | D31: product_id | E31: seller_id | F31: shipping_limit_date | G31: price | H31: freight_value
B32: 00010242fe8c5a6d1ba2dd792cb16214 | C32: 1 | D32: 4244733e06e7ecb4970a6e2683c13e61 | E32: 48436dade18ac8b2bce089ec2a041202 | F32: 2017-09-19 09:45:35 | G32: 58.9 | H32: 13.29
B33: 0008288aa423d2a3f00fcb17cd7d8719 | C33: 2 | D33: 368c6c730842d78016ad823897a372db | E33: 1f50f920176fa81dab994f9023523100 | F33: 2018-02-21 02:55:52 | G33: 49.9 | H33: 13.37
B34: 00143d0f86d6fbd9f9b38ab440ac16f5 | C34: 3 | D34: e95ee6822b66ac6058e2e4aff656071a | E34: a17f621c590ea0fab3d5d883e1630ec6 | F34: 2017-10-20 16:07:52 | G34: 21.33 | H34: 15.1
B36: olist_order_payments_dataset.csv — first 3 rows
B37: order_id | C37: payment_sequential | D37: payment_type | E37: payment_installments | F37: payment_value
B38: b81ef226f3fe1789b1e8b2acac839d17 | C38: 1 | D38: credit_card | E38: 8 | F38: 99.33
B39: 0573b5e23cbd798006520e1d5b4c6714 | C39: 1 | D39: boleto | E39: 1 | F39: 51.95
B40: 5cfd514482e22bc992e7693f0e3e8df7 | C40: 2 | D40: voucher | E40: 1 | F40: 45.17
B42: olist_order_reviews_dataset.csv — first 3 rows
B43: review_id | C43: order_id | D43: review_score | E43: review_comment_title | F43: review_comment_message | G43: review_creation_date | H43: review_answer_timestamp
B44: 8670d52e15e00043ae7de4c01cc2fe06 | C44: b9bf720beb4ab3728760088589c62129 | D44: 4 | E44: recomendo | F44: aparelho eficiente. no site a marca do aparelho esta impresso como 3desinfector e ao chegar esta com outro nome...atualizar com a marca correta uma vez que é o mesmo aparelho | G44: 2018-05-22 00:00:00 | H44: 2018-05-23 16:45:47
B45: 3948b09f7c818e2d86c9a546758b2335 | C45: e51478e7e277a83743b6f9991dbfa3fb | D45: 5 | E45: Super recomendo | F45: Vendedor confiável, produto ok e entrega antes do prazo. | G45: 2018-05-23 00:00:00 | H45: 2018-05-24 03:00:01
B46: 373cbeecea8286a2b66c97b1b157ec46 | C46: 583174fbe37d3d5f0d6661be3aad1786 | D46: 1 | E46: Não chegou meu produto | F46: Péssimo | G46: 2018-08-15 00:00:00 | H46: 2018-08-15 04:10:37

Sheet 03_KPI_Dashboard
B2: Data Overview & KPIs
B5: Scale & Coverage
B6: Metric | C6: Value
B7: Total orders | C7: =_xlfn.XLOOKUP(B7,_data_calc!$A:$A,_data_calc!$B:$B,0) -> 99441
B8: Unique customers | C8: =_xlfn.XLOOKUP(B8,_data_calc!$A:$A,_data_calc!$B:$B,0) -> 96096
B9: Sellers | C9: =_xlfn.XLOOKUP(B9,_data_calc!$A:$A,_data_calc!$B:$B,0) -> 3095
B10: Products | C10: =_xlfn.XLOOKUP(B10,_data_calc!$A:$A,_data_calc!$B:$B,0) -> 32951
B11: Product categories | C11: =_xlfn.XLOOKUP(B11,_data_calc!$A:$A,_data_calc!$B:$B,0) -> 71
B12: States covered | C12: =_xlfn.XLOOKUP(B12,_data_calc!$A:$A,_data_calc!$B:$B,0) -> 27
B13: Cities covered | C13: =_xlfn.XLOOKUP(B13,_data_calc!$A:$A,_data_calc!$B:$B,0) -> 4119
B14: Total GMV (R$) | C14: =_xlfn.XLOOKUP(B14,_data_calc!$A:$A,_data_calc!$B:$B,0) -> 13591644
B15: AOV (R$) | C15: =_xlfn.XLOOKUP(B15,_data_calc!$A:$A,_data_calc!$B:$B,0) -> 137.41
B18: Year-over-Year KPIs
B19: Year | C19: GMV (R$ M) | D19: Orders | E19: Avg Review | F19: Avg Delivery (days)
B20: 2016 | C20: =_xlfn.XLOOKUP(B20,_data_calc!$A:$A,_data_calc!$B:$B,0) -> 0.04 | D20: =_xlfn.XLOOKUP(B20,_data_calc!$A:$A,_data_calc!$C:$C,0) -> 264 | E20: =_xlfn.XLOOKUP(B20,_data_calc!$A:$A,_data_calc!$D:$D,0) -> 3.9 | F20: =_xlfn.XLOOKUP(B20,_data_calc!$A:$A,_data_calc!$E:$E,0) -> 19.6
B21: 2017 | C21: =_xlfn.XLOOKUP(B21,_data_calc!$A:$A,_data_calc!$B:$B,0) -> 5.94 | D21: =_xlfn.XLOOKUP(B21,_data_calc!$A:$A,_data_calc!$C:$C,0) -> 43098 | E21: =_xlfn.XLOOKUP(B21,_data_calc!$A:$A,_data_calc!$D:$D,0) -> 4.1 | F21: =_xlfn.XLOOKUP(B21,_data_calc!$A:$A,_data_calc!$E:$E,0) -> 12.9
B22: 2018 | C22: =_xlfn.XLOOKUP(B22,_data_calc!$A:$A,_data_calc!$B:$B,0) -> 7.19 | D22: =_xlfn.XLOOKUP(B22,_data_calc!$A:$A,_data_calc!$C:$C,0) -> 52462 | E22: =_xlfn.XLOOKUP(B22,_data_calc!$A:$A,_data_calc!$D:$D,0) -> 4.1 | F22: =_xlfn.XLOOKUP(B22,_data_calc!$A:$A,_data_calc!$E:$E,0) -> 12
B25: Order Status Distribution (from raw)
B26: Status | C26: Orders | D26: Share
B27: delivered | C27: =_xlfn.XLOOKUP(B27,_data_calc!$A:$A,_data_calc!$B:$B,0) -> 96478 | D27: =C27/SUM($C$27:$C$31) -> 0.97020344
B28: shipped | C28: =_xlfn.XLOOKUP(B28,_data_calc!$A:$A,_data_calc!$B:$B,0) -> 1107 | D28: =C28/SUM($C$27:$C$31) -> 0.011132229
B29: canceled | C29: =_xlfn.XLOOKUP(B29,_data_calc!$A:$A,_data_calc!$B:$B,0) -> 625 | D29: =C29/SUM($C$27:$C$31) -> 0.0062851339
B30: unavailable | C30: =_xlfn.XLOOKUP(B30,_data_calc!$A:$A,_data_calc!$B:$B,0) -> 609 | D30: =C30/SUM($C$27:$C$31) -> 0.0061242345
B31: other | C31: =_xlfn.XLOOKUP(B31,_data_calc!$A:$A,_data_calc!$B:$B,0) -> 622 | D31: =C31/SUM($C$27:$C$31) -> 0.0062549653
B34: Payment Mix (from raw)
B35: Payment type | C35: Orders | D35: Share | E35: Avg installments
B36: credit_card | C36: =_xlfn.XLOOKUP(B36,_data_calc!$A:$A,_data_calc!$B:$B,0) -> 76505 | D36: =C36/SUM($C$36:$C$39) -> 0.75238732 | E36: =_xlfn.XLOOKUP(B36,_data_calc!$A:$A,_data_calc!$D:$D,0) -> 3.51
B37: boleto | C37: =_xlfn.XLOOKUP(B37,_data_calc!$A:$A,_data_calc!$B:$B,0) -> 19784 | D37: =C37/SUM($C$36:$C$39) -> 0.19456546 | E37: =_xlfn.XLOOKUP(B37,_data_calc!$A:$A,_data_calc!$D:$D,0) -> 1
B38: voucher | C38: =_xlfn.XLOOKUP(B38,_data_calc!$A:$A,_data_calc!$B:$B,0) -> 3866 | D38: =C38/SUM($C$36:$C$39) -> 0.038020121 | E38: =_xlfn.XLOOKUP(B38,_data_calc!$A:$A,_data_calc!$D:$D,0) -> 1
B39: debit_card | C39: =_xlfn.XLOOKUP(B39,_data_calc!$A:$A,_data_calc!$B:$B,0) -> 1528 | D39: =C39/SUM($C$36:$C$39) -> 0.015027094 | E39: =_xlfn.XLOOKUP(B39,_data_calc!$A:$A,_data_calc!$D:$D,0) -> 1

Sheet 04_Revenue_Trend
B2: Monthly Revenue Trend (2017–2018)
B5: Month | C5: Revenue (R$)
B6: 2017-01 | C6: =_xlfn.XLOOKUP(B6,_data_calc!$A:$A,_data_calc!$B:$B,0) -> 111798.36
B7: 2017-02 | C7: =_xlfn.XLOOKUP(B7,_data_calc!$A:$A,_data_calc!$B:$B,0) -> 234223.4
B8: 2017-03 | C8: =_xlfn.XLOOKUP(B8,_data_calc!$A:$A,_data_calc!$B:$B,0) -> 359198.85
B9: 2017-04 | C9: =_xlfn.XLOOKUP(B9,_data_calc!$A:$A,_data_calc!$B:$B,0) -> 340669.68
B10: 2017-05 | C10: =_xlfn.XLOOKUP(B10,_data_calc!$A:$A,_data_calc!$B:$B,0) -> 489338.25
B11: 2017-06 | C11: =_xlfn.XLOOKUP(B11,_data_calc!$A:$A,_data_calc!$B:$B,0) -> 421923.37
B12: 2017-07 | C12: =_xlfn.XLOOKUP(B12,_data_calc!$A:$A,_data_calc!$B:$B,0) -> 481604.52
B13: 2017-08 | C13: =_xlfn.XLOOKUP(B13,_data_calc!$A:$A,_data_calc!$B:$B,0) -> 554699.7
B14: 2017-09 | C14: =_xlfn.XLOOKUP(B14,_data_calc!$A:$A,_data_calc!$B:$B,0) -> 607399.67
B15: 2017-10 | C15: =_xlfn.XLOOKUP(B15,_data_calc!$A:$A,_data_calc!$B:$B,0) -> 648247.65
B16: 2017-11 | C16: =_xlfn.XLOOKUP(B16,_data_calc!$A:$A,_data_calc!$B:$B,0) -> 987765.37
B17: 2017-12 | C17: =_xlfn.XLOOKUP(B17,_data_calc!$A:$A,_data_calc!$B:$B,0) -> 726033.19
... B25: 2018-08 | C25: =_xlfn.XLOOKUP(B25,_data_calc!$A:$A,_data_calc!$B:$B,0) -> 838576.64

Sheet 05_RFM_Segments
B2: RFM Customer Segmentation
B3: Champions + At-Risk = 40% customers, 67% revenue.
B5: Segment | C5: Customers | D5: Customer % | E5: Revenue (R$) | F5: Revenue % | G5: ARPU (R$) | H5: Avg Recency (d) | I5: Persona / Action
B6: Champions | C6: =_xlfn.XLOOKUP(B6,_data_calc!$A:$A,_data_calc!$B:$B,0) -> 15151 | D6: =_xlfn.XLOOKUP(B6,_data_calc!$A:$A,_data_calc!$C:$C,0) -> 0.162 | E6: =_xlfn.XLOOKUP(B6,_data_calc!$A:$A,_data_calc!$D:$D,0) -> 4155457.5 | F6: =_xlfn.XLOOKUP(B6,_data_calc!$A:$A,_data_calc!$E:$E,0) -> 0.314 | G6: =_xlfn.XLOOKUP(B6,_data_calc!$A:$A,_data_calc!$F:$F,0) -> 274.3 | H6: =_xlfn.XLOOKUP(B6,_data_calc!$A:$A,_data_calc!$G:$G,0) -> 90.9 | I6: Big-ticket buyer, ordered last month — protect, upsell
B7: At Risk | C7: =_xlfn.XLOOKUP(B7,_data_calc!$A:$A,_data_calc!$B:$B,0) -> 21975 | D7: =_xlfn.XLOOKUP(B7,_data_calc!$A:$A,_data_calc!$C:$C,0) -> 0.235 | E7: =_xlfn.XLOOKUP(B7,_data_calc!$A:$A,_data_calc!$D:$D,0) -> 4688537.4 | F7: =_xlfn.XLOOKUP(B7,_data_calc!$A:$A,_data_calc!$E:$E,0) -> 0.355 | G7: =_xlfn.XLOOKUP(B7,_data_calc!$A:$A,_data_calc!$F:$F,0) -> 213.4 | H7: =_xlfn.XLOOKUP(B7,_data_calc!$A:$A,_data_calc!$G:$G,0) -> 393.2 | I7: High-value customer dormant ~13 months — top win-back priority
B8: Loyal Low-spend | C8: =_xlfn.XLOOKUP(B8,_data_calc!$A:$A,_data_calc!$B:$B,0) -> 7612 | D8: =_xlfn.XLOOKUP(B8,_data_calc!$A:$A,_data_calc!$C:$C,0) -> 0.082 | E8: =_xlfn.XLOOKUP(B8,_data_calc!$A:$A,_data_calc!$D:$D,0) -> 675660.2 | F8: =_xlfn.XLOOKUP(B8,_data_calc!$A:$A,_data_calc!$E:$E,0) -> 0.051 | G8: =_xlfn.XLOOKUP(B8,_data_calc!$A:$A,_data_calc!$F:$F,0) -> 88.8 | H8: =_xlfn.XLOOKUP(B8,_data_calc!$A:$A,_data_calc!$G:$G,0) -> 90.1 | I8: Recent + frequent but low ticket. Bundle / category expansion
B9: Average | C9: =_xlfn.XLOOKUP(B9,_data_calc!$A:$A,_data_calc!$B:$B,0) -> 18672 | D9: =_xlfn.XLOOKUP(B9,_data_calc!$A:$A,_data_calc!$C:$C,0) -> 0.2 | E9: =_xlfn.XLOOKUP(B9,_data_calc!$A:$A,_data_calc!$D:$D,0) -> 2507492.9 | F9: =_xlfn.XLOOKUP(B9,_data_calc!$A:$A,_data_calc!$E:$E,0) -> 0.19 | G9: =_xlfn.XLOOKUP(B9,_data_calc!$A:$A,_data_calc!$F:$F,0) -> 134.3 | H9: =_xlfn.XLOOKUP(B9,_data_calc!$A:$A,_data_calc!$G:$G,0) -> 219.4 | I9: Mid-frequency, mid-value. Cross-sell test bed
B10: Potential New | C10: =_xlfn.XLOOKUP(B10,_data_calc!$A:$A,_data_calc!$B:$B,0) -> 14579 | D10: =_xlfn.XLOOKUP(B10,_data_calc!$A:$A,_data_calc!$C:$C,0) -> 0.156 | E10: =_xlfn.XLOOKUP(B10,_data_calc!$A:$A,_data_calc!$D:$D,0) -> 576513.3 | F10: =_xlfn.XLOOKUP(B10,_data_calc!$A:$A,_data_calc!$E:$E,0) -> 0.044 | G10: =_xlfn.XLOOKUP(B10,_data_calc!$A:$A,_data_calc!$F:$F,0) -> 39.5 | H10: =_xlfn.XLOOKUP(B10,_data_calc!$A:$A,_data_calc!$G:$G,0) -> 88.8 | I10: Just acquired, low ticket. Onboarding nurture
B11: Lost | C11: =_xlfn.XLOOKUP(B11,_data_calc!$A:$A,_data_calc!$B:$B,0) -> 15369 | D11: =_xlfn.XLOOKUP(B11,_data_calc!$A:$A,_data_calc!$C:$C,0) -> 0.165 | E11: =_xlfn.XLOOKUP(B11,_data_calc!$A:$A,_data_calc!$D:$D,0) -> 617836.7 | F11: =_xlfn.XLOOKUP(B11,_data_calc!$A:$A,_data_calc!$E:$E,0) -> 0.047 | G11: =_xlfn.XLOOKUP(B11,_data_calc!$A:$A,_data_calc!$F:$F,0) -> 40.2 | H11: =_xlfn.XLOOKUP(B11,_data_calc!$A:$A,_data_calc!$G:$G,0) -> 395.5 | I11: Long inactive + low value. Lowest priority

Sheet 06_Cohort_Heatmap
B2: Cohort Retention Heatmap
B3: Cell = % of cohort active in month N (benchmark M1: 5-15%).
B5: Cohort | C5: M0 | D5: M1 | E5: M2 | F5: M3 | G5: M4 | H5: M5 | I5: M6 | J5: M7 | K5: M8 | L5: M9 | M5: M10 | N5: M11 | O5: M12
B6: 2017-01 | C6: =INDEX(_data_calc!$B$92:$N$111,MATCH($B6,_data_calc!$A$92:$A$111,0),MATCH(C$5,_data_calc!$B$91:$N$91,0)) -> 1 | D6: =INDEX(_data_calc!$B$92:$N$111,MATCH($B6,_data_calc!$A$92:$A$111,0),MATCH(D$5,_data_calc!$B$91:$N$91,0)) -> 0.0027894003 | E6: =INDEX(_data_calc!$B$92:$N$111,MATCH($B6,_data_calc!$A$92:$A$111,0),MATCH(E$5,_data_calc!$B$91:$N$91,0)) -> 0.0027894003 | F6: =INDEX(_data_calc!$B$92:$N$111,MATCH($B6,_data_calc!$A$92:$A$111,0),MATCH(F$5,_data_calc!$B$91:$N$91,0)) -> 0.0013947001 | G6: =INDEX(_data_calc!$B$92:$N$111,MATCH($B6,_data_calc!$A$92:$A$111,0),MATCH(G$5,_data_calc!$B$91:$N$91,0)) -> 0.0041841004 | H6: =INDEX(_data_calc!$B$92:$N$111,MATCH($B6,_data_calc!$A$92:$A$111,0),MATCH(H$5,_data_calc!$B$91:$N$91,0)) -> 0.0013947001 | I6: =INDEX(_data_calc!$B$92:$N$111,MATCH($B6,_data_calc!$A$92:$A$111,0),MATCH(I$5,_data_calc!$B$91:$N$91,0)) -> 0.0041841004 | J6: =INDEX(_data_calc!$B$92:$N$111,MATCH($B6,_data_calc!$A$92:$A$111,0),MATCH(J$5,_data_calc!$B$91:$N$91,0)) -> 0.0013947001 | ... O6: =INDEX(_data_calc!$B$92:$N$111,MATCH($B6,_data_calc!$A$92:$A$111,0),MATCH(O$5,_data_calc!$B$91:$N$91,0)) -> 0.0069735007
B7: 2017-02 | C7: =INDEX(_data_calc!$B$92:$N$111,MATCH($B7,_data_calc!$A$92:$A$111,0),MATCH(C$5,_data_calc!$B$91:$N$91,0)) -> 1 | D7: =INDEX(_data_calc!$B$92:$N$111,MATCH($B7,_data_calc!$A$92:$A$111,0),MATCH(D$5,_data_calc!$B$91:$N$91,0)) -> 0.0018427518 | E7: =INDEX(_data_calc!$B$92:$N$111,MATCH($B7,_data_calc!$A$92:$A$111,0),MATCH(E$5,_data_calc!$B$91:$N$91,0)) -> 0.0030712531 | F7: =INDEX(_data_calc!$B$92:$N$111,MATCH($B7,_data_calc!$A$92:$A$111,0),MATCH(F$5,_data_calc!$B$91:$N$91,0)) -> 0.0012285012 | G7: =INDEX(_data_calc!$B$92:$N$111,MATCH($B7,_data_calc!$A$92:$A$111,0),MATCH(G$5,_data_calc!$B$91:$N$91,0)) -> 0.0042997543 | H7: =INDEX(_data_calc!$B$92:$N$111,MATCH($B7,_data_calc!$A$92:$A$111,0),MATCH(H$5,_data_calc!$B$91:$N$91,0)) -> 0.0012285012 | I7: =INDEX(_data_calc!$B$92:$N$111,MATCH($B7,_data_calc!$A$92:$A$111,0),MATCH(I$5,_data_calc!$B$91:$N$91,0)) -> 0.0024570025 | J7: =INDEX(_data_calc!$B$92:$N$111,MATCH($B7,_data_calc!$A$92:$A$111,0),MATCH(J$5,_data_calc!$B$91:$N$91,0)) -> 0.0018427518 | ... O7: =INDEX(_data_calc!$B$92:$N$111,MATCH($B7,_data_calc!$A$92:$A$111,0),MATCH(O$5,_data_calc!$B$91:$N$91,0)) -> 0.0012285012
B8: 2017-03 | C8: =INDEX(_data_calc!$B$92:$N$111,MATCH($B8,_data_calc!$A$92:$A$111,0),MATCH(C$5,_data_calc!$B$91:$N$91,0)) -> 1 | D8: =INDEX(_data_calc!$B$92:$N$111,MATCH($B8,_data_calc!$A$92:$A$111,0),MATCH(D$5,_data_calc!$B$91:$N$91,0)) -> 0.0043947263 | E8: =INDEX(_data_calc!$B$92:$N$111,MATCH($B8,_data_calc!$A$92:$A$111,0),MATCH(E$5,_data_calc!$B$91:$N$91,0)) -> 0.0035956852 | F8: =INDEX(_data_calc!$B$92:$N$111,MATCH($B8,_data_calc!$A$92:$A$111,0),MATCH(F$5,_data_calc!$B$91:$N$91,0)) -> 0.0039952058 | G8: =INDEX(_data_calc!$B$92:$N$111,MATCH($B8,_data_calc!$A$92:$A$111,0),MATCH(G$5,_data_calc!$B$91:$N$91,0)) -> 0.0035956852 | H8: =INDEX(_data_calc!$B$92:$N$111,MATCH($B8,_data_calc!$A$92:$A$111,0),MATCH(H$5,_data_calc!$B$91:$N$91,0)) -> 0.0015980823 | I8: =INDEX(_data_calc!$B$92:$N$111,MATCH($B8,_data_calc!$A$92:$A$111,0),MATCH(I$5,_data_calc!$B$91:$N$91,0)) -> 0.0015980823 | J8: =INDEX(_data_calc!$B$92:$N$111,MATCH($B8,_data_calc!$A$92:$A$111,0),MATCH(J$5,_data_calc!$B$91:$N$91,0)) -> 0.0031961646 | ... O8: =INDEX(_data_calc!$B$92:$N$111,MATCH($B8,_data_calc!$A$92:$A$111,0),MATCH(O$5,_data_calc!$B$91:$N$91,0)) -> 0.0019976029
B9: 2017-04 | C9: =INDEX(_data_calc!$B$92:$N$111,MATCH($B9,_data_calc!$A$92:$A$111,0),MATCH(C$5,_data_calc!$B$91:$N$91,0)) -> 1 | D9: =INDEX(_data_calc!$B$92:$N$111,MATCH($B9,_data_calc!$A$92:$A$111,0),MATCH(D$5,_data_calc!$B$91:$N$91,0)) -> 0.0062056738 | E9: =INDEX(_data_calc!$B$92:$N$111,MATCH($B9,_data_calc!$A$92:$A$111,0),MATCH(E$5,_data_calc!$B$91:$N$91,0)) -> 0.0022163121 | F9: =INDEX(_data_calc!$B$92:$N$111,MATCH($B9,_data_calc!$A$92:$A$111,0),MATCH(F$5,_data_calc!$B$91:$N$91,0)) -> 0.0017730496 | G9: =INDEX(_data_calc!$B$92:$N$111,MATCH($B9,_data_calc!$A$92:$A$111,0),MATCH(G$5,_data_calc!$B$91:$N$91,0)) -> 0.0026595745 | H9: =INDEX(_data_calc!$B$92:$N$111,MATCH($B9,_data_calc!$A$92:$A$111,0),MATCH(H$5,_data_calc!$B$91:$N$91,0)) -> 0.0026595745 | I9: =INDEX(_data_calc!$B$92:$N$111,MATCH($B9,_data_calc!$A$92:$A$111,0),MATCH(I$5,_data_calc!$B$91:$N$91,0)) -> 0.0035460993 | J9: =INDEX(_data_calc!$B$92:$N$111,MATCH($B9,_data_calc!$A$92:$A$111,0),MATCH(J$5,_data_calc!$B$91:$N$91,0)) -> 0.0031028369 | ... O9: =INDEX(_data_calc!$B$92:$N$111,MATCH($B9,_data_calc!$A$92:$A$111,0),MATCH(O$5,_data_calc!$B$91:$N$91,0)) -> 0.00044326241
B10: 2017-05 | C10: =INDEX(_data_calc!$B$92:$N$111,MATCH($B10,_data_calc!$A$92:$A$111,0),MATCH(C$5,_data_calc!$B$91:$N$91,0)) -> 1 | D10: =INDEX(_data_calc!$B$92:$N$111,MATCH($B10,_data_calc!$A$92:$A$111,0),MATCH(D$5,_data_calc!$B$91:$N$91,0)) -> 0.0046363373 | E10: =INDEX(_data_calc!$B$92:$N$111,MATCH($B10,_data_calc!$A$92:$A$111,0),MATCH(E$5,_data_calc!$B$91:$N$91,0)) -> 0.0046363373 | F10: =INDEX(_data_calc!$B$92:$N$111,MATCH($B10,_data_calc!$A$92:$A$111,0),MATCH(F$5,_data_calc!$B$91:$N$91,0)) -> 0.0028977108 | G10: =INDEX(_data_calc!$B$92:$N$111,MATCH($B10,_data_calc!$A$92:$A$111,0),MATCH(G$5,_data_calc!$B$91:$N$91,0)) -> 0.0028977108 | H10: =INDEX(_data_calc!$B$92:$N$111,MATCH($B10,_data_calc!$A$92:$A$111,0),MATCH(H$5,_data_calc!$B$91:$N$91,0)) -> 0.0031874819 | I10: =INDEX(_data_calc!$B$92:$N$111,MATCH($B10,_data_calc!$A$92:$A$111,0),MATCH(I$5,_data_calc!$B$91:$N$91,0)) -> 0.0040567951 | J10: =INDEX(_data_calc!$B$92:$N$111,MATCH($B10,_data_calc!$A$92:$A$111,0),MATCH(J$5,_data_calc!$B$91:$N$91,0)) -> 0.0014488554 | ... O10: =INDEX(_data_calc!$B$92:$N$111,MATCH($B10,_data_calc!$A$92:$A$111,0),MATCH(O$5,_data_calc!$B$91:$N$91,0)) -> 0.0023181686
B11: 2017-06 | C11: =INDEX(_data_calc!$B$92:$N$111,MATCH($B11,_data_calc!$A$92:$A$111,0),MATCH(C$5,_data_calc!$B$91:$N$91,0)) -> 1 | D11: =INDEX(_data_calc!$B$92:$N$111,MATCH($B11,_data_calc!$A$92:$A$111,0),MATCH(D$5,_data_calc!$B$91:$N$91,0)) -> 0.0049390846 | E11: =INDEX(_data_calc!$B$92:$N$111,MATCH($B11,_data_calc!$A$92:$A$111,0),MATCH(E$5,_data_calc!$B$91:$N$91,0)) -> 0.0039512677 | F11: =INDEX(_data_calc!$B$92:$N$111,MATCH($B11,_data_calc!$A$92:$A$111,0),MATCH(F$5,_data_calc!$B$91:$N$91,0)) -> 0.00428054 | G11: =INDEX(_data_calc!$B$92:$N$111,MATCH($B11,_data_calc!$A$92:$A$111,0),MATCH(G$5,_data_calc!$B$91:$N$91,0)) -> 0.0029634508 | H11: =INDEX(_data_calc!$B$92:$N$111,MATCH($B11,_data_calc!$A$92:$A$111,0),MATCH(H$5,_data_calc!$B$91:$N$91,0)) -> 0.0039512677 | I11: =INDEX(_data_calc!$B$92:$N$111,MATCH($B11,_data_calc!$A$92:$A$111,0),MATCH(I$5,_data_calc!$B$91:$N$91,0)) -> 0.0036219954 | J11: =INDEX(_data_calc!$B$92:$N$111,MATCH($B11,_data_calc!$A$92:$A$111,0),MATCH(J$5,_data_calc!$B$91:$N$91,0)) -> 0.0023049062 | ... O11: =INDEX(_data_calc!$B$92:$N$111,MATCH($B11,_data_calc!$A$92:$A$111,0),MATCH(O$5,_data_calc!$B$91:$N$91,0)) -> 0.0016463615
B12: 2017-07 | C12: =INDEX(_data_calc!$B$92:$N$111,MATCH($B12,_data_calc!$A$92:$A$111,0),MATCH(C$5,_data_calc!$B$91:$N$91,0)) -> 1 | D12: =INDEX(_data_calc!$B$92:$N$111,MATCH($B12,_data_calc!$A$92:$A$111,0),MATCH(D$5,_data_calc!$B$91:$N$91,0)) -> 0.0053304904 | E12: =INDEX(_data_calc!$B$92:$N$111,MATCH($B12,_data_calc!$A$92:$A$111,0),MATCH(E$5,_data_calc!$B$91:$N$91,0)) -> 0.0034648188 | F12: =INDEX(_data_calc!$B$92:$N$111,MATCH($B12,_data_calc!$A$92:$A$111,0),MATCH(F$5,_data_calc!$B$91:$N$91,0)) -> 0.0023987207 | G12: =INDEX(_data_calc!$B$92:$N$111,MATCH($B12,_data_calc!$A$92:$A$111,0),MATCH(G$5,_data_calc!$B$91:$N$91,0)) -> 0.0029317697 | H12: =INDEX(_data_calc!$B$92:$N$111,MATCH($B12,_data_calc!$A$92:$A$111,0),MATCH(H$5,_data_calc!$B$91:$N$91,0)) -> 0.0021321962 | I12: =INDEX(_data_calc!$B$92:$N$111,MATCH($B12,_data_calc!$A$92:$A$111,0),MATCH(I$5,_data_calc!$B$91:$N$91,0)) -> 0.0031982942 | J12: =INDEX(_data_calc!$B$92:$N$111,MATCH($B12,_data_calc!$A$92:$A$111,0),MATCH(J$5,_data_calc!$B$91:$N$91,0)) -> 0.0010660981 | ... O12: =INDEX(_data_calc!$B$92:$N$111,MATCH($B12,_data_calc!$A$92:$A$111,0),MATCH(O$5,_data_calc!$B$91:$N$91,0)) -> 0.0013326226
B13: 2017-08 | C13: =INDEX(_data_calc!$B$92:$N$111,MATCH($B13,_data_calc!$A$92:$A$111,0),MATCH(C$5,_data_calc!$B$91:$N$91,0)) -> 1 | D13: =INDEX(_data_calc!$B$92:$N$111,MATCH($B13,_data_calc!$A$92:$A$111,0),MATCH(D$5,_data_calc!$B$91:$N$91,0)) -> 0.0069016515 | E13: =INDEX(_data_calc!$B$92:$N$111,MATCH($B13,_data_calc!$A$92:$A$111,0),MATCH(E$5,_data_calc!$B$91:$N$91,0)) -> 0.0034508257 | F13: =INDEX(_data_calc!$B$92:$N$111,MATCH($B13,_data_calc!$A$92:$A$111,0),MATCH(F$5,_data_calc!$B$91:$N$91,0)) -> 0.0027113631 | G13: =INDEX(_data_calc!$B$92:$N$111,MATCH($B13,_data_calc!$A$92:$A$111,0),MATCH(G$5,_data_calc!$B$91:$N$91,0)) -> 0.0034508257 | H13: =INDEX(_data_calc!$B$92:$N$111,MATCH($B13,_data_calc!$A$92:$A$111,0),MATCH(H$5,_data_calc!$B$91:$N$91,0)) -> 0.0051762386 | I13: =INDEX(_data_calc!$B$92:$N$111,MATCH($B13,_data_calc!$A$92:$A$111,0),MATCH(I$5,_data_calc!$B$91:$N$91,0)) -> 0.0029578506 | J13: =INDEX(_data_calc!$B$92:$N$111,MATCH($B13,_data_calc!$A$92:$A$111,0),MATCH(J$5,_data_calc!$B$91:$N$91,0)) -> 0.0027113631 | ... O13: =INDEX(_data_calc!$B$92:$N$111,MATCH($B13,_data_calc!$A$92:$A$111,0),MATCH(O$5,_data_calc!$B$91:$N$91,0)) -> 0.0012324378
B14: 2017-09 | C14: =INDEX(_data_calc!$B$92:$N$111,MATCH($B14,_data_calc!$A$92:$A$111,0),MATCH(C$5,_data_calc!$B$91:$N$91,0)) -> 1 | D14: =INDEX(_data_calc!$B$92:$N$111,MATCH($B14,_data_calc!$A$92:$A$111,0),MATCH(D$5,_data_calc!$B$91:$N$91,0)) -> 0.006993007 | E14: =INDEX(_data_calc!$B$92:$N$111,MATCH($B14,_data_calc!$A$92:$A$111,0),MATCH(E$5,_data_calc!$B$91:$N$91,0)) -> 0.0054945055 | F14: =INDEX(_data_calc!$B$92:$N$111,MATCH($B14,_data_calc!$A$92:$A$111,0),MATCH(F$5,_data_calc!$B$91:$N$91,0)) -> 0.0027472527 | G14: =INDEX(_data_calc!$B$92:$N$111,MATCH($B14,_data_calc!$A$92:$A$111,0),MATCH(G$5,_data_calc!$B$91:$N$91,0)) -> 0.0044955045 | H14: =INDEX(_data_calc!$B$92:$N$111,MATCH($B14,_data_calc!$A$92:$A$111,0),MATCH(H$5,_data_calc!$B$91:$N$91,0)) -> 0.0022477522 | I14: =INDEX(_data_calc!$B$92:$N$111,MATCH($B14,_data_calc!$A$92:$A$111,0),MATCH(I$5,_data_calc!$B$91:$N$91,0)) -> 0.0022477522 | J14: =INDEX(_data_calc!$B$92:$N$111,MATCH($B14,_data_calc!$A$92:$A$111,0),MATCH(J$5,_data_calc!$B$91:$N$91,0)) -> 0.0024975025 | ... O14: =INDEX(_data_calc!$B$92:$N$111,MATCH($B14,_data_calc!$A$92:$A$111,0),MATCH(O$5,_data_calc!$B$91:$N$91,0)) -> 0
B15: 2017-10 | C15: =INDEX(_data_calc!$B$92:$N$111,MATCH($B15,_data_calc!$A$92:$A$111,0),MATCH(C$5,_data_calc!$B$91:$N$91,0)) -> 1 | D15: =INDEX(_data_calc!$B$92:$N$111,MATCH($B15,_data_calc!$A$92:$A$111,0),MATCH(D$5,_data_calc!$B$91:$N$91,0)) -> 0.0071626617 | E15: =INDEX(_data_calc!$B$92:$N$111,MATCH($B15,_data_calc!$A$92:$A$111,0),MATCH(E$5,_data_calc!$B$91:$N$91,0)) -> 0.0025415896 | F15: =INDEX(_data_calc!$B$92:$N$111,MATCH($B15,_data_calc!$A$92:$A$111,0),MATCH(F$5,_data_calc!$B$91:$N$91,0)) -> 0.00092421442 | G15: =INDEX(_data_calc!$B$92:$N$111,MATCH($B15,_data_calc!$A$92:$A$111,0),MATCH(G$5,_data_calc!$B$91:$N$91,0)) -> 0.002310536 | H15: =INDEX(_data_calc!$B$92:$N$111,MATCH($B15,_data_calc!$A$92:$A$111,0),MATCH(H$5,_data_calc!$B$91:$N$91,0)) -> 0.0020794824 | I15: =INDEX(_data_calc!$B$92:$N$111,MATCH($B15,_data_calc!$A$92:$A$111,0),MATCH(I$5,_data_calc!$B$91:$N$91,0)) -> 0.0020794824 | J15: =INDEX(_data_calc!$B$92:$N$111,MATCH($B15,_data_calc!$A$92:$A$111,0),MATCH(J$5,_data_calc!$B$91:$N$91,0)) -> 0.0036968577 | ... O15: =INDEX(_data_calc!$B$92:$N$111,MATCH($B15,_data_calc!$A$92:$A$111,0),MATCH(O$5,_data_calc!$B$91:$N$91,0)) -> 0
B16: 2017-11 | C16: =INDEX(_data_calc!$B$92:$N$111,MATCH($B16,_data_calc!$A$92:$A$111,0),MATCH(C$5,_data_calc!$B$91:$N$91,0)) -> 1 | D16: =INDEX(_data_calc!$B$92:$N$111,MATCH($B16,_data_calc!$A$92:$A$111,0),MATCH(D$5,_data_calc!$B$91:$N$91,0)) -> 0.0056657224 | E16: =INDEX(_data_calc!$B$92:$N$111,MATCH($B16,_data_calc!$A$92:$A$111,0),MATCH(E$5,_data_calc!$B$91:$N$91,0)) -> 0.0036827195 | F16: =INDEX(_data_calc!$B$92:$N$111,MATCH($B16,_data_calc!$A$92:$A$111,0),MATCH(F$5,_data_calc!$B$91:$N$91,0)) -> 0.0016997167 | G16: =INDEX(_data_calc!$B$92:$N$111,MATCH($B16,_data_calc!$A$92:$A$111,0),MATCH(G$5,_data_calc!$B$91:$N$91,0)) -> 0.0016997167 | H16: =INDEX(_data_calc!$B$92:$N$111,MATCH($B16,_data_calc!$A$92:$A$111,0),MATCH(H$5,_data_calc!$B$91:$N$91,0)) -> 0.0018413598 | I16: =INDEX(_data_calc!$B$92:$N$111,MATCH($B16,_data_calc!$A$92:$A$111,0),MATCH(I$5,_data_calc!$B$91:$N$91,0)) -> 0.0011331445 | J16: =INDEX(_data_calc!$B$92:$N$111,MATCH($B16,_data_calc!$A$92:$A$111,0),MATCH(J$5,_data_calc!$B$91:$N$91,0)) -> 0.0018413598 | ... O16: =INDEX(_data_calc!$B$92:$N$111,MATCH($B16,_data_calc!$A$92:$A$111,0),MATCH(O$5,_data_calc!$B$91:$N$91,0)) -> 0
B17: 2017-12 | C17: =INDEX(_data_calc!$B$92:$N$111,MATCH($B17,_data_calc!$A$92:$A$111,0),MATCH(C$5,_data_calc!$B$91:$N$91,0)) -> 1 | D17: =INDEX(_data_calc!$B$92:$N$111,MATCH($B17,_data_calc!$A$92:$A$111,0),MATCH(D$5,_data_calc!$B$91:$N$91,0)) -> 0.0020606969 | E17: =INDEX(_data_calc!$B$92:$N$111,MATCH($B17,_data_calc!$A$92:$A$111,0),MATCH(E$5,_data_calc!$B$91:$N$91,0)) -> 0.0028100412 | F17: =INDEX(_data_calc!$B$92:$N$111,MATCH($B17,_data_calc!$A$92:$A$111,0),MATCH(F$5,_data_calc!$B$91:$N$91,0)) -> 0.0033720495 | G17: =INDEX(_data_calc!$B$92:$N$111,MATCH($B17,_data_calc!$A$92:$A$111,0),MATCH(G$5,_data_calc!$B$91:$N$91,0)) -> 0.0026227051 | H17: =INDEX(_data_calc!$B$92:$N$111,MATCH($B17,_data_calc!$A$92:$A$111,0),MATCH(H$5,_data_calc!$B$91:$N$91,0)) -> 0.0020606969 | I17: =INDEX(_data_calc!$B$92:$N$111,MATCH($B17,_data_calc!$A$92:$A$111,0),MATCH(I$5,_data_calc!$B$91:$N$91,0)) -> 0.0016860247 | J17: =INDEX(_data_calc!$B$92:$N$111,MATCH($B17,_data_calc!$A$92:$A$111,0),MATCH(J$5,_data_calc!$B$91:$N$91,0)) -> 0.00018733608 | ... O17: =INDEX(_data_calc!$B$92:$N$111,MATCH($B17,_data_calc!$A$92:$A$111,0),MATCH(O$5,_data_calc!$B$91:$N$91,0)) -> 0
... B25: 2018-08 | C25: =INDEX(_data_calc!$B$92:$N$111,MATCH($B25,_data_calc!$A$92:$A$111,0),MATCH(C$5,_data_calc!$B$91:$N$91,0)) -> 1 | D25: =INDEX(_data_calc!$B$92:$N$111,MATCH($B25,_data_calc!$A$92:$A$111,0),MATCH(D$5,_data_calc!$B$91:$N$91,0)) -> 0 | E25: =INDEX(_data_calc!$B$92:$N$111,MATCH($B25,_data_calc!$A$92:$A$111,0),MATCH(E$5,_data_calc!$B$91:$N$91,0)) -> 0 | F25: =INDEX(_data_calc!$B$92:$N$111,MATCH($B25,_data_calc!$A$92:$A$111,0),MATCH(F$5,_data_calc!$B$91:$N$91,0)) -> 0 | G25: =INDEX(_data_calc!$B$92:$N$111,MATCH($B25,_data_calc!$A$92:$A$111,0),MATCH(G$5,_data_calc!$B$91:$N$91,0)) -> 0 | H25: =INDEX(_data_calc!$B$92:$N$111,MATCH($B25,_data_calc!$A$92:$A$111,0),MATCH(H$5,_data_calc!$B$91:$N$91,0)) -> 0 | I25: =INDEX(_data_calc!$B$92:$N$111,MATCH($B25,_data_calc!$A$92:$A$111,0),MATCH(I$5,_data_calc!$B$91:$N$91,0)) -> 0 | J25: =INDEX(_data_calc!$B$92:$N$111,MATCH($B25,_data_calc!$A$92:$A$111,0),MATCH(J$5,_data_calc!$B$91:$N$91,0)) -> 0 | ... O25: =INDEX(_data_calc!$B$92:$N$111,MATCH($B25,_data_calc!$A$92:$A$111,0),MATCH(O$5,_data_calc!$B$91:$N$91,0)) -> 0

Sheet 07_ROI_Calculator
B2: At-Risk Win-back ROI Calculator
B3: Edit yellow cells — scenarios recompute live.
B5: INPUTS — edit me
B6: Parameter | C6: Value | D6: Format | E6: Notes
B7: At-risk customers (segment size) | C7: =_xlfn.XLOOKUP("At Risk",_data_calc!$A:$A,_data_calc!$B:$B,0) -> 21975 | D7: #,##0 | E7: XLOOKUP from RFM segment
B8: Avg ARPU per customer (R$) | C8: =_xlfn.XLOOKUP("At Risk",_data_calc!$A:$A,_data_calc!$F:$F,0) -> 213.4 | D8: 0 | E8: XLOOKUP from RFM segment
B9: Repeat-spend rate (% of ARPU on win-back order) | C9: 0.5 | D9: 0% | E9: Modeling assumption (50% of historical avg)
B10: Total CRM cost (R$) | C10: 50000 | D10: #,##0 | E10: Budget assumption (email + discount voucher)
B13: SCENARIO OUTPUTS — recomputes live
B14: Metric | C14: Conservative (5%) | D14: Optimistic (10%) | E14: Aggressive (20%) | F14: Custom
B15: Recall rate (%) | C15: 0.05 | D15: 0.1 | E15: 0.2 | F15: 0.1
B16: Recalled customers | C16: =At_Risk_Count*C15 -> 1098.75 | D16: =At_Risk_Count*D15 -> 2197.5 | E16: =At_Risk_Count*E15 -> 4395 | F16: =At_Risk_Count*F15 -> 2197.5
B17: Incremental revenue (R$) | C17: =At_Risk_Count*C15*ARPU*Repeat_Spend -> 117236.62 | D17: =At_Risk_Count*D15*ARPU*Repeat_Spend -> 234473.25 | E17: =At_Risk_Count*E15*ARPU*Repeat_Spend -> 468946.5 | F17: =At_Risk_Count*F15*ARPU*Repeat_Spend -> 234473.25
B18: CRM cost (R$) | C18: =CRM_Cost -> 50000 | D18: =CRM_Cost -> 50000 | E18: =CRM_Cost -> 50000 | F18: =CRM_Cost -> 50000
B19: Net contribution (R$) | C19: =C17-C18 -> 67236.625 | D19: =D17-D18 -> 184473.25 | E19: =E17-E18 -> 418946.5 | F19: =F17-F18 -> 184473.25
B20: ROI (×) | C20: =C17/C18 -> 2.3447325 | D20: =D17/D18 -> 4.689465 | E20: =E17/E18 -> 9.37893 | F20: =F17/F18 -> 4.689465
B22: FORMULA
B23: Incremental revenue = At_Risk_Count × Recall rate × ARPU × Repeat_Spend
B24: ROI = Incremental revenue ÷ CRM_Cost

Sheet 08_Installments
B2: Installments — AOV & Repeat Rate by Bucket
B3: 73.9% of orders use credit_card, avg 3.5 installments.
B5: Installment bucket | C5: Orders | D5: Avg ticket (R$) | E5: Customers | F5: Repeat rate
B6: 1 (single) | C6: =_xlfn.XLOOKUP(B6,_data_calc!$A:$A,_data_calc!$B:$B,0) -> 25455 | D6: =_xlfn.XLOOKUP(B6,_data_calc!$A:$A,_data_calc!$F:$F,0)/C6 -> 95.870006 | E6: =_xlfn.XLOOKUP(B6,_data_calc!$A:$A,_data_calc!$D:$D,0) -> 23931 | F6: =_xlfn.XLOOKUP(B6,_data_calc!$A:$A,_data_calc!$G:$G,0)/E6 -> 0.025113869
B7: 2-3 installments | C7: =_xlfn.XLOOKUP(B7,_data_calc!$A:$A,_data_calc!$B:$B,0) -> 22874 | D7: =_xlfn.XLOOKUP(B7,_data_calc!$A:$A,_data_calc!$F:$F,0)/C7 -> 134.23 | E7: =_xlfn.XLOOKUP(B7,_data_calc!$A:$A,_data_calc!$D:$D,0) -> 21502 | F7: =_xlfn.XLOOKUP(B7,_data_calc!$A:$A,_data_calc!$G:$G,0)/E7 -> 0.02809041
B8: 4-6 installments | C8: =_xlfn.XLOOKUP(B8,_data_calc!$A:$A,_data_calc!$B:$B,0) -> 16257 | D8: =_xlfn.XLOOKUP(B8,_data_calc!$A:$A,_data_calc!$F:$F,0)/C8 -> 181.31999 | E8: =_xlfn.XLOOKUP(B8,_data_calc!$A:$A,_data_calc!$D:$D,0) -> 15173 | F8: =_xlfn.XLOOKUP(B8,_data_calc!$A:$A,_data_calc!$G:$G,0)/E8 -> 0.031832861
B9: 7-10 installments | C9: =_xlfn.XLOOKUP(B9,_data_calc!$A:$A,_data_calc!$B:$B,0) -> 11866 | D9: =_xlfn.XLOOKUP(B9,_data_calc!$A:$A,_data_calc!$F:$F,0)/C9 -> 333.83002 | E9: =_xlfn.XLOOKUP(B9,_data_calc!$A:$A,_data_calc!$D:$D,0) -> 10966 | F9: =_xlfn.XLOOKUP(B9,_data_calc!$A:$A,_data_calc!$G:$G,0)/E9 -> 0.041309502
B10: 11+ installments | C10: =_xlfn.XLOOKUP(B10,_data_calc!$A:$A,_data_calc!$B:$B,0) -> 341 | D10: =_xlfn.XLOOKUP(B10,_data_calc!$A:$A,_data_calc!$F:$F,0)/C10 -> 358.34018 | E10: =_xlfn.XLOOKUP(B10,_data_calc!$A:$A,_data_calc!$D:$D,0) -> 311 | F10: =_xlfn.XLOOKUP(B10,_data_calc!$A:$A,_data_calc!$G:$G,0)/E10 -> 0.041800643

Sheet 09_Logistics
B2: Logistics — Estimated vs Actual Delivery (by State)
B3: National avg: 15.4 actual / 24 ETA days (36% under-promise).
B5: State | C5: Actual days | D5: Estimated days | E5: ETA gap (days)
B6: SP | C6: =_xlfn.XLOOKUP(B6,_data_calc!$A:$A,_data_calc!$B:$B,0) -> 8.8 | D6: =_xlfn.XLOOKUP(B6,_data_calc!$A:$A,_data_calc!$C:$C,0) -> 19.1 | E6: =D6-C6 -> 10.3
B7: MG | C7: =_xlfn.XLOOKUP(B7,_data_calc!$A:$A,_data_calc!$B:$B,0) -> 12 | D7: =_xlfn.XLOOKUP(B7,_data_calc!$A:$A,_data_calc!$C:$C,0) -> 24.5 | E7: =D7-C7 -> 12.5
B8: PR | C8: =_xlfn.XLOOKUP(B8,_data_calc!$A:$A,_data_calc!$B:$B,0) -> 12 | D8: =_xlfn.XLOOKUP(B8,_data_calc!$A:$A,_data_calc!$C:$C,0) -> 24.6 | E8: =D8-C8 -> 12.6
B9: DF | C9: =_xlfn.XLOOKUP(B9,_data_calc!$A:$A,_data_calc!$B:$B,0) -> 13 | D9: =_xlfn.XLOOKUP(B9,_data_calc!$A:$A,_data_calc!$C:$C,0) -> 24.3 | E9: =D9-C9 -> 11.3
B10: SC | C10: =_xlfn.XLOOKUP(B10,_data_calc!$A:$A,_data_calc!$B:$B,0) -> 15 | D10: =_xlfn.XLOOKUP(B10,_data_calc!$A:$A,_data_calc!$C:$C,0) -> 25.8 | E10: =D10-C10 -> 10.8
B11: RJ | C11: =_xlfn.XLOOKUP(B11,_data_calc!$A:$A,_data_calc!$B:$B,0) -> 15.3 | D11: =_xlfn.XLOOKUP(B11,_data_calc!$A:$A,_data_calc!$C:$C,0) -> 26.4 | E11: =D11-C11 -> 11.1
B12: RS | C12: =_xlfn.XLOOKUP(B12,_data_calc!$A:$A,_data_calc!$B:$B,0) -> 15.3 | D12: =_xlfn.XLOOKUP(B12,_data_calc!$A:$A,_data_calc!$C:$C,0) -> 28.5 | E12: =D12-C12 -> 13.2
B13: GO | C13: =_xlfn.XLOOKUP(B13,_data_calc!$A:$A,_data_calc!$B:$B,0) -> 15.6 | D13: =_xlfn.XLOOKUP(B13,_data_calc!$A:$A,_data_calc!$C:$C,0) -> 27.1 | E13: =D13-C13 -> 11.5
B14: MS | C14: =_xlfn.XLOOKUP(B14,_data_calc!$A:$A,_data_calc!$B:$B,0) -> 15.6 | D14: =_xlfn.XLOOKUP(B14,_data_calc!$A:$A,_data_calc!$C:$C,0) -> 26 | E14: =D14-C14 -> 10.4
B15: ES | C15: =_xlfn.XLOOKUP(B15,_data_calc!$A:$A,_data_calc!$B:$B,0) -> 15.8 | D15: =_xlfn.XLOOKUP(B15,_data_calc!$A:$A,_data_calc!$C:$C,0) -> 25.6 | E15: =D15-C15 -> 9.8
B16: TO | C16: =_xlfn.XLOOKUP(B16,_data_calc!$A:$A,_data_calc!$B:$B,0) -> 17.7 | D16: =_xlfn.XLOOKUP(B16,_data_calc!$A:$A,_data_calc!$C:$C,0) -> 29.1 | E16: =D16-C16 -> 11.4
B17: MT | C17: =_xlfn.XLOOKUP(B17,_data_calc!$A:$A,_data_calc!$B:$B,0) -> 18.1 | D17: =_xlfn.XLOOKUP(B17,_data_calc!$A:$A,_data_calc!$C:$C,0) -> 31.7 | E17: =D17-C17 -> 13.6
... B20: RN | C20: =_xlfn.XLOOKUP(B20,_data_calc!$A:$A,_data_calc!$B:$B,0) -> 19.3 | D20: =_xlfn.XLOOKUP(B20,_data_calc!$A:$A,_data_calc!$C:$C,0) -> 32.2 | E20: =D20-C20 -> 12.9

Sheet 10_Pivot_Analysis
B2: PivotTable — Orders by State × Payment Type
B4: PivotTable (built by Excel COM post-save) | I4: Source: tbl_payments_long
B5: 加總 - Orders | C5: 欄標籤 | I5: State | J5: Payment type | K5: Orders
B6: 列標籤 | C6: boleto | D6: credit_card | E6: debit_card | F6: voucher | G6: 總計 | I6: SP | J6: credit_card | K6: 32074
B7: AC | C7: 16 | D7: 61 | E7: 2 | F7: 4 | G7: 83 | I7: SP | J7: boleto | K7: 8205
B8: AL | C8: 68 | D8: 338 | E8: 5 | F8: 10 | G8: 421 | I8: SP | J8: voucher | K8: 1596
B9: AM | C9: 21 | D9: 124 | E9: 2 | F9: 4 | G9: 151 | I9: SP | J9: debit_card | K9: 759
B10: AP | C10: 20 | D10: 47 | F10: 3 | G10: 70 | I10: RJ | J10: credit_card | K10: 10253
B11: BA | C11: 614 | D11: 2643 | E11: 53 | F11: 176 | G11: 3486 | I11: RJ | J11: boleto | K11: 2163
B12: CE | C12: 205 | D12: 1083 | E12: 20 | F12: 59 | G12: 1367 | I12: RJ | J12: voucher | K12: 547
B13: DF | C13: 396 | D13: 1695 | E13: 17 | F13: 79 | G13: 2187 | I13: RJ | J13: debit_card | K13: 185
B14: ES | C14: 403 | D14: 1568 | E14: 27 | F14: 82 | G14: 2080 | I14: MG | J14: credit_card | K14: 9030
B15: GO | C15: 449 | D15: 1514 | E15: 22 | F15: 76 | G15: 2061 | I15: MG | J15: boleto | K15: 2304
B16: MA | C16: 203 | D16: 534 | E16: 4 | F16: 19 | G16: 760 | I16: MG | J16: voucher | K16: 438
B17: MG | C17: 2304 | D17: 9030 | E17: 139 | F17: 438 | G17: 11911 | I17: MG | J17: debit_card | K17: 139
B18: MS | C18: 175 | D18: 516 | E18: 11 | F18: 24 | G18: 726 | I18: RS | J18: credit_card | K18: 3967
B19: MT | C19: 238 | D19: 657 | E19: 6 | F19: 25 | G19: 926 | I19: RS | J19: boleto | K19: 1359
B20: PA | C20: 215 | D20: 724 | E20: 16 | F20: 41 | G20: 996 | I20: RS | J20: voucher | K20: 179
B21: PB | C21: 93 | D21: 421 | E21: 13 | F21: 23 | G21: 550 | I21: RS | J21: debit_card | K21: 76
B22: PE | C22: 277 | D22: 1326 | E22: 19 | F22: 73 | G22: 1695 | I22: PR | J22: credit_card | K22: 3776
... B27: RO | C27: 64 | D27: 184 | E27: 3 | F27: 7 | G27: 258 | I27: SC | J27: boleto | K27: 840
B28: RR | C28: 13 | D28: 33 | G28: 46 | I28: SC | J28: voucher | K28: 127
B29: RS | C29: 1359 | D29: 3967 | E29: 76 | F29: 179 | G29: 5581 | I29: SC | J29: debit_card | K29: 46
B30: SC | C30: 840 | D30: 2705 | E30: 46 | F30: 127 | G30: 3718 | I30: BA | J30: credit_card | K30: 2643
B31: SE | C31: 75 | D31: 263 | E31: 5 | F31: 15 | G31: 358 | I31: BA | J31: boleto | K31: 614
B32: SP | C32: 8205 | D32: 32074 | E32: 759 | F32: 1596 | G32: 42634 | I32: BA | J32: voucher | K32: 176
B33: TO | C33: 76 | D33: 196 | E33: 4 | F33: 12 | G33: 288 | I33: BA | J33: debit_card | K33: 53
B34: 總計 | C34: 19784 | D34: 76505 | E34: 1528 | F34: 3866 | G34: 101683 | I34: DF | J34: credit_card | K34: 1695
I35: DF | J35: boleto | K35: 396
I36: DF | J36: voucher | K36: 79
I37: DF | J37: debit_card | K37: 17
I38: ES | J38: credit_card | K38: 1568
I39: ES | J39: boleto | K39: 403
I40: ES | J40: voucher | K40: 82
I41: ES | J41: debit_card | K41: 27
I42: GO | J42: credit_card | K42: 1514
I43: GO | J43: boleto | K43: 449
I44: GO | J44: voucher | K44: 76
I45: GO | J45: debit_card | K45: 22
I46: PE | J46: credit_card | K46: 1326
...

Sheet _data_calc
A1: KPI Lookup
A2: Metric | B2: Value | C2: Format
A3: Total orders | B3: 99441 | C3: #,##0
A4: Unique customers | B4: 96096 | C4: #,##0
A5: Sellers | B5: 3095 | C5: #,##0
A6: Products | B6: 32951 | C6: #,##0
A7: Product categories | B7: 71 | C7: #,##0
A8: States covered | B8: 27 | C8: 0
A9: Cities covered | B9: 4119 | C9: #,##0
A10: Total GMV (R$) | B10: 13591644 | C10: #,##0
A11: AOV (R$) | B11: 137.41 | C11: 0.00
A12: Cross-month repeat rate | B12: 0.0181 | C12: 0.00%
A13: Champions ARPU (R$) | B13: 274 | C13: 0
A14: At-Risk customers | B14: 21975 | C14: #,##0
... A18: Repeat customers (count) | B18: 1693 | C18: #,##0
A21: Yearly KPIs
A22: Year | B22: GMV (R$ M) | C22: Orders | D22: Avg Review | E22: Avg Delivery (days)
A23: 2016 | B23: 0.04 | C23: 264 | D23: 3.9 | E23: 19.6
A24: 2017 | B24: 5.94 | C24: 43098 | D24: 4.1 | E24: 12.9
A25: 2018 | B25: 7.19 | C25: 52462 | D25: 4.1 | E25: 12
A28: Monthly Revenue
A29: Month | B29: Revenue (R$)
A30: 2017-01 | B30: 111798.36
A31: 2017-02 | B31: 234223.4
A32: 2017-03 | B32: 359198.85
A33: 2017-04 | B33: 340669.68
A34: 2017-05 | B34: 489338.25
A35: 2017-06 | B35: 421923.37
A36: 2017-07 | B36: 481604.52
A37: 2017-08 | B37: 554699.7
A38: 2017-09 | B38: 607399.67
A39: 2017-10 | B39: 648247.65
A40: 2017-11 | B40: 987765.37
A41: 2017-12 | B41: 726033.19
... A49: 2018-08 | B49: 838576.64
A52: RFM Segments
A53: Segment | B53: Customers | C53: Customer % | D53: Revenue (R$) | E53: Revenue % | F53: ARPU (R$) | G53: Avg Recency (d)
A54: Champions | B54: 15151 | C54: 0.162 | D54: 4155457.5 | E54: 0.314 | F54: 274.3 | G54: 90.9
A55: At Risk | B55: 21975 | C55: 0.235 | D55: 4688537.4 | E55: 0.355 | F55: 213.4 | G55: 393.2
A56: Loyal Low-spend | B56: 7612 | C56: 0.082 | D56: 675660.2 | E56: 0.051 | F56: 88.8 | G56: 90.1
...
